Traceback (most recent call last):
  File "/Users/rahmatullaev/Documents/projects/.venv/lib/python3.13/site-packages/jupyter_core/utils/__init__.py", line 154, in wrapped
    asyncio.get_running_loop()
    ~~~~~~~~~~~~~~~~~~~~~~~~^^
RuntimeError: no running event loop

During handling of the above exception, another exception occurred:

Traceback (most recent call last):
  File "/Users/rahmatullaev/Documents/projects/.venv/lib/python3.13/site-packages/jupyter_cache/executors/utils.py", line 58, in single_nb_execution
    executenb(
    ~~~~~~~~~^
        nb,
        ^^^
    ...<4 lines>...
        **kwargs,
        ^^^^^^^^^
    )
    ^
  File "/Users/rahmatullaev/Documents/projects/.venv/lib/python3.13/site-packages/nbclient/client.py", line 1305, in execute
    return NotebookClient(nb=nb, resources=resources, km=km, **kwargs).execute()
           ~~~~~~~~~~~~~~~~~~~~~~~~~~~~~~~~~~~~~~~~~~~~~~~~~~~~~~~~~~~~~~~~~~~^^
  File "/Users/rahmatullaev/Documents/projects/.venv/lib/python3.13/site-packages/jupyter_core/utils/__init__.py", line 158, in wrapped
    return loop.run_until_complete(inner)
           ~~~~~~~~~~~~~~~~~~~~~~~^^^^^^^
  File "/opt/homebrew/Cellar/python@3.13/3.13.2/Frameworks/Python.framework/Versions/3.13/lib/python3.13/asyncio/base_events.py", line 725, in run_until_complete
    return future.result()
           ~~~~~~~~~~~~~^^
  File "/Users/rahmatullaev/Documents/projects/.venv/lib/python3.13/site-packages/nbclient/client.py", line 705, in async_execute
    await self.async_execute_cell(
        cell, index, execution_count=self.code_cells_executed + 1
    )
  File "/Users/rahmatullaev/Documents/projects/.venv/lib/python3.13/site-packages/nbclient/client.py", line 1058, in async_execute_cell
    await self._check_raise_for_error(cell, cell_index, exec_reply)
  File "/Users/rahmatullaev/Documents/projects/.venv/lib/python3.13/site-packages/nbclient/client.py", line 914, in _check_raise_for_error
    raise CellExecutionError.from_cell_and_msg(cell, exec_reply_content)
nbclient.exceptions.CellExecutionError: An error occurred while executing the following cell:
------------------
fmri_image =image.load_img(fmri_filename)
------------------


[31m---------------------------------------------------------------------------[39m
[31mValueError[39m                                Traceback (most recent call last)
[36mCell[39m[36m [39m[32mIn[8][39m[32m, line 1[39m
[32m----> [39m[32m1[39m fmri_image =[43mimage[49m[43m.[49m[43mload_img[49m[43m([49m[43mfmri_filename[49m[43m)[49m

[36mFile [39m[32m~/Documents/projects/.venv/lib/python3.13/site-packages/nilearn/image/image.py:1693[39m, in [36mload_img[39m[34m(img, wildcards, dtype)[39m
[32m   1658[39m [38;5;129m@fill_doc[39m
[32m   1659[39m [38;5;28;01mdef[39;00m[38;5;250m [39m[34mload_img[39m(img, wildcards=[38;5;28;01mTrue[39;00m, dtype=[38;5;28;01mNone[39;00m):
[32m   1660[39m [38;5;250m    [39m[33;03m"""Load a Niimg-like object from filenames or list of filenames.[39;00m
[32m   1661[39m 
[32m   1662[39m [33;03m    .. versionadded:: 0.2.5[39;00m
[32m   (...)[39m[32m   1691[39m 
[32m   1692[39m [33;03m    """[39;00m
[32m-> [39m[32m1693[39m     [38;5;28;01mreturn[39;00m [43mcheck_niimg[49m[43m([49m[43mimg[49m[43m,[49m[43m [49m[43mwildcards[49m[43m=[49m[43mwildcards[49m[43m,[49m[43m [49m[43mdtype[49m[43m=[49m[43mdtype[49m[43m)[49m

[36mFile [39m[32m~/Documents/projects/.venv/lib/python3.13/site-packages/nilearn/_utils/niimg_conversions.py:338[39m, in [36mcheck_niimg[39m[34m(niimg, ensure_ndim, atleast_4d, dtype, return_iterator, wildcards)[39m
[32m    336[39m         [38;5;28;01mraise[39;00m [38;5;167;01mValueError[39;00m(message)
[32m    337[39m     [38;5;28;01melse[39;00m:
[32m--> [39m[32m338[39m         [38;5;28;01mraise[39;00m [38;5;167;01mValueError[39;00m([33mf[39m[33m"[39m[33mFile not found: [39m[33m'[39m[38;5;132;01m{[39;00mniimg[38;5;132;01m}[39;00m[33m'[39m[33m"[39m)
[32m    339[39m [38;5;28;01melif[39;00m [38;5;129;01mnot[39;00m Path(niimg).exists():
[32m    340[39m     [38;5;28;01mraise[39;00m [38;5;167;01mValueError[39;00m([33mf[39m[33m"[39m[33mFile not found: [39m[33m'[39m[38;5;132;01m{[39;00mniimg[38;5;132;01m}[39;00m[33m'[39m[33m"[39m)

[31mValueError[39m: File not found: './cobre/sub-A00000368/func/sub-A00000368_task-rest_space-MNI152NLin2009cAsym_desc-preproc_bold.nii.gz'

