Traceback (most recent call last):
  File "/opt/conda/lib/python3.11/site-packages/jupyter_cache/executors/utils.py", line 58, in single_nb_execution
    executenb(
  File "/opt/conda/lib/python3.11/site-packages/nbclient/client.py", line 1319, in execute
    return NotebookClient(nb=nb, resources=resources, km=km, **kwargs).execute()
           ^^^^^^^^^^^^^^^^^^^^^^^^^^^^^^^^^^^^^^^^^^^^^^^^^^^^^^^^^^^^^^^^^^^^^
  File "/opt/conda/lib/python3.11/site-packages/jupyter_core/utils/__init__.py", line 165, in wrapped
    return loop.run_until_complete(inner)
           ^^^^^^^^^^^^^^^^^^^^^^^^^^^^^^
  File "/opt/conda/lib/python3.11/asyncio/base_events.py", line 654, in run_until_complete
    return future.result()
           ^^^^^^^^^^^^^^^
  File "/opt/conda/lib/python3.11/site-packages/nbclient/client.py", line 709, in async_execute
    await self.async_execute_cell(
  File "/opt/conda/lib/python3.11/site-packages/nbclient/client.py", line 1062, in async_execute_cell
    await self._check_raise_for_error(cell, cell_index, exec_reply)
  File "/opt/conda/lib/python3.11/site-packages/nbclient/client.py", line 918, in _check_raise_for_error
    raise CellExecutionError.from_cell_and_msg(cell, exec_reply_content)
nbclient.exceptions.CellExecutionError: An error occurred while executing the following cell:
------------------
fmri_image =image.load_img(fmri_filename)
------------------


[0;31m---------------------------------------------------------------------------[0m
[0;31mValueError[0m                                Traceback (most recent call last)
Cell [0;32mIn[8], line 1[0m
[0;32m----> 1[0m fmri_image [38;5;241m=[39m[43mimage[49m[38;5;241;43m.[39;49m[43mload_img[49m[43m([49m[43mfmri_filename[49m[43m)[49m

File [0;32m/opt/conda/lib/python3.11/site-packages/nilearn/image/image.py:1468[0m, in [0;36mload_img[0;34m(img, wildcards, dtype)[0m
[1;32m   1431[0m [38;5;28;01mdef[39;00m[38;5;250m [39m[38;5;21mload_img[39m(img, wildcards[38;5;241m=[39m[38;5;28;01mTrue[39;00m, dtype[38;5;241m=[39m[38;5;28;01mNone[39;00m):
[1;32m   1432[0m [38;5;250m    [39m[38;5;124;03m"""Load a Niimg-like object from filenames or list of filenames.[39;00m
[1;32m   1433[0m 
[1;32m   1434[0m [38;5;124;03m    .. versionadded:: 0.2.5[39;00m
[0;32m   (...)[0m
[1;32m   1466[0m 
[1;32m   1467[0m [38;5;124;03m    """[39;00m
[0;32m-> 1468[0m     [38;5;28;01mreturn[39;00m [43mcheck_niimg[49m[43m([49m[43mimg[49m[43m,[49m[43m [49m[43mwildcards[49m[38;5;241;43m=[39;49m[43mwildcards[49m[43m,[49m[43m [49m[43mdtype[49m[38;5;241;43m=[39;49m[43mdtype[49m[43m)[49m

File [0;32m/opt/conda/lib/python3.11/site-packages/nilearn/_utils/niimg_conversions.py:302[0m, in [0;36mcheck_niimg[0;34m(niimg, ensure_ndim, atleast_4d, dtype, return_iterator, wildcards)[0m
[1;32m    300[0m         [38;5;28;01mraise[39;00m [38;5;167;01mValueError[39;00m(message)
[1;32m    301[0m     [38;5;28;01melse[39;00m:
[0;32m--> 302[0m         [38;5;28;01mraise[39;00m [38;5;167;01mValueError[39;00m([38;5;124mf[39m[38;5;124m"[39m[38;5;124mFile not found: [39m[38;5;124m'[39m[38;5;132;01m{[39;00mniimg[38;5;132;01m}[39;00m[38;5;124m'[39m[38;5;124m"[39m)
[1;32m    303[0m [38;5;28;01melif[39;00m [38;5;129;01mnot[39;00m Path(niimg)[38;5;241m.[39mexists():
[1;32m    304[0m     [38;5;28;01mraise[39;00m [38;5;167;01mValueError[39;00m([38;5;124mf[39m[38;5;124m"[39m[38;5;124mFile not found: [39m[38;5;124m'[39m[38;5;132;01m{[39;00mniimg[38;5;132;01m}[39;00m[38;5;124m'[39m[38;5;124m"[39m)

[0;31mValueError[0m: File not found: './cobre/sub-A00000368/func/sub-A00000368_task-rest_space-MNI152NLin2009cAsym_desc-preproc_bold.nii.gz'

