Traceback (most recent call last):
  File "/Users/rahmatullaev/Documents/projects/.venv/lib/python3.13/site-packages/jupyter_core/utils/__init__.py", line 154, in wrapped
    asyncio.get_running_loop()
    ~~~~~~~~~~~~~~~~~~~~~~~~^^
RuntimeError: no running event loop

During handling of the above exception, another exception occurred:

Traceback (most recent call last):
  File "/Users/rahmatullaev/Documents/projects/.venv/lib/python3.13/site-packages/jupyter_cache/executors/utils.py", line 58, in single_nb_execution
    executenb(
    ~~~~~~~~~^
        nb,
        ^^^
    ...<4 lines>...
        **kwargs,
        ^^^^^^^^^
    )
    ^
  File "/Users/rahmatullaev/Documents/projects/.venv/lib/python3.13/site-packages/nbclient/client.py", line 1305, in execute
    return NotebookClient(nb=nb, resources=resources, km=km, **kwargs).execute()
           ~~~~~~~~~~~~~~~~~~~~~~~~~~~~~~~~~~~~~~~~~~~~~~~~~~~~~~~~~~~~~~~~~~~^^
  File "/Users/rahmatullaev/Documents/projects/.venv/lib/python3.13/site-packages/jupyter_core/utils/__init__.py", line 158, in wrapped
    return loop.run_until_complete(inner)
           ~~~~~~~~~~~~~~~~~~~~~~~^^^^^^^
  File "/opt/homebrew/Cellar/python@3.13/3.13.2/Frameworks/Python.framework/Versions/3.13/lib/python3.13/asyncio/base_events.py", line 725, in run_until_complete
    return future.result()
           ~~~~~~~~~~~~~^^
  File "/Users/rahmatullaev/Documents/projects/.venv/lib/python3.13/site-packages/nbclient/client.py", line 705, in async_execute
    await self.async_execute_cell(
        cell, index, execution_count=self.code_cells_executed + 1
    )
  File "/Users/rahmatullaev/Documents/projects/.venv/lib/python3.13/site-packages/nbclient/client.py", line 1058, in async_execute_cell
    await self._check_raise_for_error(cell, cell_index, exec_reply)
  File "/Users/rahmatullaev/Documents/projects/.venv/lib/python3.13/site-packages/nbclient/client.py", line 914, in _check_raise_for_error
    raise CellExecutionError.from_cell_and_msg(cell, exec_reply_content)
nbclient.exceptions.CellExecutionError: An error occurred while executing the following cell:
------------------
%%bash
datalad get -J 4 -d /data/ds000114 /data/ds000114/derivatives/fmriprep/sub-0[2345789]/anat/*h5
------------------

----- stderr -----
bash: line 1: datalad: command not found
------------------

[31m---------------------------------------------------------------------------[39m
[31mCalledProcessError[39m                        Traceback (most recent call last)
[36mCell[39m[36m [39m[32mIn[1][39m[32m, line 1[39m
[32m----> [39m[32m1[39m [43mget_ipython[49m[43m([49m[43m)[49m[43m.[49m[43mrun_cell_magic[49m[43m([49m[33;43m'[39;49m[33;43mbash[39;49m[33;43m'[39;49m[43m,[49m[43m [49m[33;43m'[39;49m[33;43m'[39;49m[43m,[49m[43m [49m[33;43m'[39;49m[33;43mdatalad get -J 4 -d /data/ds000114 /data/ds000114/derivatives/fmriprep/sub-0[2345789]/anat/*h5[39;49m[38;5;130;43;01m\n[39;49;00m[33;43m'[39;49m[43m)[49m

[36mFile [39m[32m~/Documents/projects/.venv/lib/python3.13/site-packages/IPython/core/interactiveshell.py:2565[39m, in [36mInteractiveShell.run_cell_magic[39m[34m(self, magic_name, line, cell)[39m
[32m   2563[39m [38;5;28;01mwith[39;00m [38;5;28mself[39m.builtin_trap:
[32m   2564[39m     args = (magic_arg_s, cell)
[32m-> [39m[32m2565[39m     result = [43mfn[49m[43m([49m[43m*[49m[43margs[49m[43m,[49m[43m [49m[43m*[49m[43m*[49m[43mkwargs[49m[43m)[49m
[32m   2567[39m [38;5;66;03m# The code below prevents the output from being displayed[39;00m
[32m   2568[39m [38;5;66;03m# when using magics with decorator @output_can_be_silenced[39;00m
[32m   2569[39m [38;5;66;03m# when the last Python token in the expression is a ';'.[39;00m
[32m   2570[39m [38;5;28;01mif[39;00m [38;5;28mgetattr[39m(fn, magic.MAGIC_OUTPUT_CAN_BE_SILENCED, [38;5;28;01mFalse[39;00m):

[36mFile [39m[32m~/Documents/projects/.venv/lib/python3.13/site-packages/IPython/core/magics/script.py:160[39m, in [36mScriptMagics._make_script_magic.<locals>.named_script_magic[39m[34m(line, cell)[39m
[32m    158[39m [38;5;28;01melse[39;00m:
[32m    159[39m     line = script
[32m--> [39m[32m160[39m [38;5;28;01mreturn[39;00m [38;5;28;43mself[39;49m[43m.[49m[43mshebang[49m[43m([49m[43mline[49m[43m,[49m[43m [49m[43mcell[49m[43m)[49m

[36mFile [39m[32m~/Documents/projects/.venv/lib/python3.13/site-packages/IPython/core/magics/script.py:343[39m, in [36mScriptMagics.shebang[39m[34m(self, line, cell)[39m
[32m    338[39m [38;5;28;01mif[39;00m args.raise_error [38;5;129;01mand[39;00m p.returncode != [32m0[39m:
[32m    339[39m     [38;5;66;03m# If we get here and p.returncode is still None, we must have[39;00m
[32m    340[39m     [38;5;66;03m# killed it but not yet seen its return code. We don't wait for it,[39;00m
[32m    341[39m     [38;5;66;03m# in case it's stuck in uninterruptible sleep. -9 = SIGKILL[39;00m
[32m    342[39m     rc = p.returncode [38;5;129;01mor[39;00m -[32m9[39m
[32m--> [39m[32m343[39m     [38;5;28;01mraise[39;00m CalledProcessError(rc, cell)

[31mCalledProcessError[39m: Command 'b'datalad get -J 4 -d /data/ds000114 /data/ds000114/derivatives/fmriprep/sub-0[2345789]/anat/*h5\n'' returned non-zero exit status 127.

