Traceback (most recent call last):
  File "/Users/rahmatullaev/Documents/projects/.venv/lib/python3.13/site-packages/jupyter_core/utils/__init__.py", line 154, in wrapped
    asyncio.get_running_loop()
    ~~~~~~~~~~~~~~~~~~~~~~~~^^
RuntimeError: no running event loop

During handling of the above exception, another exception occurred:

Traceback (most recent call last):
  File "/Users/rahmatullaev/Documents/projects/.venv/lib/python3.13/site-packages/jupyter_cache/executors/utils.py", line 58, in single_nb_execution
    executenb(
    ~~~~~~~~~^
        nb,
        ^^^
    ...<4 lines>...
        **kwargs,
        ^^^^^^^^^
    )
    ^
  File "/Users/rahmatullaev/Documents/projects/.venv/lib/python3.13/site-packages/nbclient/client.py", line 1305, in execute
    return NotebookClient(nb=nb, resources=resources, km=km, **kwargs).execute()
           ~~~~~~~~~~~~~~~~~~~~~~~~~~~~~~~~~~~~~~~~~~~~~~~~~~~~~~~~~~~~~~~~~~~^^
  File "/Users/rahmatullaev/Documents/projects/.venv/lib/python3.13/site-packages/jupyter_core/utils/__init__.py", line 158, in wrapped
    return loop.run_until_complete(inner)
           ~~~~~~~~~~~~~~~~~~~~~~~^^^^^^^
  File "/opt/homebrew/Cellar/python@3.13/3.13.2/Frameworks/Python.framework/Versions/3.13/lib/python3.13/asyncio/base_events.py", line 725, in run_until_complete
    return future.result()
           ~~~~~~~~~~~~~^^
  File "/Users/rahmatullaev/Documents/projects/.venv/lib/python3.13/site-packages/nbclient/client.py", line 705, in async_execute
    await self.async_execute_cell(
        cell, index, execution_count=self.code_cells_executed + 1
    )
  File "/Users/rahmatullaev/Documents/projects/.venv/lib/python3.13/site-packages/nbclient/client.py", line 1058, in async_execute_cell
    await self._check_raise_for_error(cell, cell_index, exec_reply)
  File "/Users/rahmatullaev/Documents/projects/.venv/lib/python3.13/site-packages/nbclient/client.py", line 914, in _check_raise_for_error
    raise CellExecutionError.from_cell_and_msg(cell, exec_reply_content)
nbclient.exceptions.CellExecutionError: An error occurred while executing the following cell:
------------------
import nibabel
from nilearn import plotting
import matplotlib
import numpy as np
import warnings
warnings.filterwarnings('ignore')


anat = nibabel.load('/data/ds000114/derivatives/fmriprep/sub-01/anat/sub-01_t1w_preproc.nii.gz')
fmri = nibabel.load('/data/ds000114/sub-01/ses-test/func/sub-01_ses-test_task-fingerfootlips_bold.nii.gz')
------------------


[31m---------------------------------------------------------------------------[39m
[31mFileNotFoundError[39m                         Traceback (most recent call last)
[36mFile [39m[32m~/Documents/projects/.venv/lib/python3.13/site-packages/nibabel/loadsave.py:101[39m, in [36mload[39m[34m(filename, **kwargs)[39m
[32m    100[39m [38;5;28;01mtry[39;00m:
[32m--> [39m[32m101[39m     stat_result = [43mos[49m[43m.[49m[43mstat[49m[43m([49m[43mfilename[49m[43m)[49m
[32m    102[39m [38;5;28;01mexcept[39;00m [38;5;167;01mOSError[39;00m:

[31mFileNotFoundError[39m: [Errno 2] No such file or directory: '/data/ds000114/derivatives/fmriprep/sub-01/anat/sub-01_t1w_preproc.nii.gz'

During handling of the above exception, another exception occurred:

[31mFileNotFoundError[39m                         Traceback (most recent call last)
[36mCell[39m[36m [39m[32mIn[1][39m[32m, line 9[39m
[32m      5[39m [38;5;28;01mimport[39;00m[38;5;250m [39m[34;01mwarnings[39;00m
[32m      6[39m warnings.filterwarnings([33m'[39m[33mignore[39m[33m'[39m)
[32m----> [39m[32m9[39m anat = [43mnibabel[49m[43m.[49m[43mload[49m[43m([49m[33;43m'[39;49m[33;43m/data/ds000114/derivatives/fmriprep/sub-01/anat/sub-01_t1w_preproc.nii.gz[39;49m[33;43m'[39;49m[43m)[49m
[32m     10[39m fmri = nibabel.load([33m'[39m[33m/data/ds000114/sub-01/ses-test/func/sub-01_ses-test_task-fingerfootlips_bold.nii.gz[39m[33m'[39m)

[36mFile [39m[32m~/Documents/projects/.venv/lib/python3.13/site-packages/nibabel/loadsave.py:103[39m, in [36mload[39m[34m(filename, **kwargs)[39m
[32m    101[39m     stat_result = os.stat(filename)
[32m    102[39m [38;5;28;01mexcept[39;00m [38;5;167;01mOSError[39;00m:
[32m--> [39m[32m103[39m     [38;5;28;01mraise[39;00m [38;5;167;01mFileNotFoundError[39;00m([33mf[39m[33m"[39m[33mNo such file or no access: [39m[33m'[39m[38;5;132;01m{[39;00mfilename[38;5;132;01m}[39;00m[33m'[39m[33m"[39m)
[32m    104[39m [38;5;28;01mif[39;00m stat_result.st_size <= [32m0[39m:
[32m    105[39m     [38;5;28;01mraise[39;00m ImageFileError([33mf[39m[33m"[39m[33mEmpty file: [39m[33m'[39m[38;5;132;01m{[39;00mfilename[38;5;132;01m}[39;00m[33m'[39m[33m"[39m)

[31mFileNotFoundError[39m: No such file or no access: '/data/ds000114/derivatives/fmriprep/sub-01/anat/sub-01_t1w_preproc.nii.gz'

